<?xml version='1.0' encoding='utf-8'?>
<robot xmlns:xacro="http://www.ros.org/wiki/xacro" name="robocol">
  <xacro:macro name="robocol_arm" params="arm_id:='robocol' description_pkg:='robocol_new_arm' connected_to:='' xyz:='0 0 0' rpy:='0 0 0'">
    <xacro:unless value="${not connected_to}">
      <joint name="${arm_id}_joint_${connected_to}" type="fixed">
        <parent link="${connected_to}"/>
        <child link="${arm_id}_link0"/>
        <origin rpy="${rpy}" xyz="${xyz}"/>
      </joint>
    </xacro:unless>
    <material name="joints_mat">
      <color rgba="0.75 0.6 0.3 1"/>
    </material>
    <link name="${arm_id}_link0">
      <visual>
        <geometry>
          <mesh filename="package://${description_pkg}/meshes/visual/link0.stl" scale="0.1 0.1 0.1"/>
        </geometry>
        <material name="joints_mat"/>
      </visual>
      <collision>
        <geometry>
          <mesh filename="package://${description_pkg}/meshes/collision/link0.stl" scale="0.1 0.1 0.1"/>
        </geometry>
      </collision>
    </link>
    <link name="${arm_id}_link1">
      <visual>
        <geometry>
          <mesh filename="package://${description_pkg}/meshes/visual/link1.stl" scale="0.1 0.1 0.1"/>
        </geometry>
        <material name="joints_mat"/>
      </visual>
      <collision>
        <geometry>
          <mesh filename="package://${description_pkg}/meshes/collision/link1.stl" scale="0.1 0.1 0.1"/>
        </geometry>
      </collision>
    </link>
    <joint name="${arm_id}_joint1" type="revolute">
      <safety_controller k_position="100.0" k_velocity="40.0" soft_lower_limit="-3" soft_upper_limit="3"/>
      <origin rpy="0 0 0" xyz="0 0 1.4"/>
      <parent link="${arm_id}_link0"/>
      <child link="${arm_id}_link1"/>
      <axis xyz="0 0 1"/>
      <limit effort="87" lower="-3" upper="3" velocity="2.1750"/>
    </joint>
    <link name="${arm_id}_link2">
      <visual>
        <geometry>
          <mesh filename="package://${description_pkg}/meshes/visual/link2.stl" scale="0.1 0.1 0.1"/>
        </geometry>
        <material name="joints_mat"/>
      </visual>
      <collision>
        <geometry>
          <mesh filename="package://${description_pkg}/meshes/collision/link2.stl" scale="0.1 0.1 0.1"/>
        </geometry>
      </collision>
    </link>
    <joint name="${arm_id}_joint2" type="revolute">
      <safety_controller k_position="100.0" k_velocity="40.0" soft_lower_limit="-1.7628" soft_upper_limit="2.5"/>
      <origin rpy="0 ${-pi/2} 0" xyz="0.74 -0.55 1.2"/>
      <parent link="${arm_id}_link1"/>
      <child link="${arm_id}_link2"/>
      <axis xyz="0 1 0"/>
      <limit effort="87" lower="-1.7628" upper="2.5" velocity="2.1750"/>
    </joint>
    <link name="${arm_id}_link3">
      <visual>
        <geometry>
          <mesh filename="package://${description_pkg}/meshes/visual/link3.stl" scale="0.1 0.1 0.1"/>
        </geometry>
        <material name="joints_mat"/>
      </visual>
      <collision>
        <geometry>
          <mesh filename="package://${description_pkg}/meshes/collision/link3.stl" scale="0.1 0.1 0.1"/>
        </geometry>
      </collision>
    </link>
    <joint name="${arm_id}_joint3" type="revolute">
      <safety_controller k_position="100.0" k_velocity="40.0" soft_lower_limit="-2.6" soft_upper_limit="2.6"/>
      <origin rpy="0 ${pi/2} 0" xyz="2.5 0 0"/>
      <parent link="${arm_id}_link2"/>
      <child link="${arm_id}_link3"/>
      <axis xyz="0 1 0"/>
      <limit effort="87" lower="-2.6" upper="2.6" velocity="2.1750"/>
    </joint>
    <link name="${arm_id}_link4">
      <visual>
        <geometry>
          <mesh filename="package://${description_pkg}/meshes/visual/link4.stl" scale="0.1 0.1 0.1"/>
        </geometry>
        <material name="joints_mat"/>
      </visual>
      <collision>
        <geometry>
          <mesh filename="package://${description_pkg}/meshes/collision/link4.stl" scale="0.1 0.1 0.1"/>
        </geometry>
      </collision>
    </link>
    <joint name="${arm_id}_joint4" type="revolute">
      <safety_controller k_position="100.0" k_velocity="40.0" soft_lower_limit="-2.5" soft_upper_limit="2.5"/>
      <origin rpy="0 0 ${-pi/2}" xyz="-0.05 0.55 1.5"/>
      <parent link="${arm_id}_link3"/>
      <child link="${arm_id}_link4"/>
      <axis xyz="0 0 1"/>
      <limit effort="87" lower="-2.5" upper="2.5" velocity="2.1750"/>
    </joint>
    <link name="${arm_id}_link5">
      <visual>
        <geometry>
          <mesh filename="package://${description_pkg}/meshes/visual/link5.stl" scale="0.1 0.1 0.1"/>
        </geometry>
        <material name="joints_mat"/>
      </visual>
      <collision>
        <geometry>
          <mesh filename="package://${description_pkg}/meshes/collision/link5.stl" scale="0.1 0.1 0.1"/>
        </geometry>
      </collision>
    </link>
    <joint name="${arm_id}_joint5" type="revolute">
      <safety_controller k_position="100.0" k_velocity="40.0" soft_lower_limit="-2.5" soft_upper_limit="2.5"/>
      <origin rpy="0 0 0" xyz="0.42 0.04 1.53"/>
      <parent link="${arm_id}_link4"/>
      <child link="${arm_id}_link5"/>
      <axis xyz="1 0 0"/>
      <limit effort="12" lower="-2.5" upper="2.5" velocity="2.6100"/>
    </joint>
    <link name="${arm_id}_link6"/>
    <joint name="${arm_id}_joint6" type="revolute">
      <safety_controller k_position="100.0" k_velocity="40.0" soft_lower_limit="-3" soft_upper_limit="3"/>
      <origin rpy="0 0 -0.8" xyz="-0.3 0.1 1.4"/>
      <parent link="${arm_id}_link5"/>
      <child link="${arm_id}_link6"/>
      <axis xyz="0 0 1"/>
      <limit effort="12" lower="-3" upper="3" velocity="2.6100"/>
    </joint>
  </xacro:macro>
</robot>
